Workbook

Sheet Leia-me
A1: DICIONÁRIO DO INDICADOR · APONTAMENTO DE MÃO DE OBRA DA MANUTENÇÃO
A2: Usina Lins Agroindustrial · PCM · alinhado a ABNT NBR ISO 55001 (9.1 – monitoramento, medição, análise e avaliação) e ISO 14224 (horas-homem de manutenção)
A4: Sigla | B4: Indicador | C4: Fórmula | D4: Meta | E4: Frequência | F4: Onde é calculado | G4: Para que serve / como agir
A5: IAP | B5: % Apontamento (ponderado) | C5: Σ horas apontadas ÷ Σ horas disponíveis, no recorte selecionado | D5: ≥ 80% | E5: Diária / semanal / mensal | F5: Base Diária · col. L e M | G5: Mede o quanto da jornada disponível virou registro em ordem de manutenção. Indicador de VOLUME. Ponderado: um dia de 8,8 h pesa mais que um dia de 6,67 h.
A6: IAM | B6: % Aderência (dias na meta) | C6: Dias-empregado com apontamento ≥ meta ÷ dias-empregado trabalhados | D6: ≥ 80% | E6: Diária / semanal / mensal | F6: Base Diária · col. R | G6: Mede CONSISTÊNCIA. Expõe o que a média esconde: quem faz 60% e 100% tem média 80%, mas aderência 50%.
A7: IHR | B7: Horas a recuperar | C7: Σ MAX(0 ; horas disponíveis × meta − horas apontadas) nos dias trabalhados | D7: Minimizar | E7: Diária / semanal / mensal | F7: Base Diária · col. S | G7: Converte o gap percentual em HORAS-HOMEM — a linguagem da gerência. Base para custeio da mão de obra indireta.
A8: ICE | B8: Cobertura do efetivo | C8: Empregados com IAP ≥ meta ÷ efetivo mensurável do centro | D8: ≥ 80% | E8: Semanal / mensal | F8: Painel Empregado · col. Q | G8: Mostra se o resultado do centro vem do time inteiro ou de poucos "puxadores". Direciona a ação para a pessoa, não para a área.
A9: IDA | B9: Faltas de registro | C9: Dias-empregado classificados como dia de trabalho no ciclo e sem nenhuma hora apontada | D9: Investigar 100% | E9: Diária | F9: Base Diária · col. Y = "Falta de registro" | G9: QUALIDADE DO DADO. Separa FOLGA, FÉRIAS/AFASTAMENTO e FALTA. O ciclo de cada escala diz se o dia era de trabalho; uma ausência acima do limite de Parâmetros!E16 vira afastamento. O que sobra é falha de lançamento ou ausência pontual do colaborador — a planilha não distingue os dois.
A10: ISA | B10: Sobre-apontamento | C10: Dias-empregado acima da tolerância de Parâmetros!E15 | D10: Investigar 100% | E10: Diária | F10: Base Diária · col. T | G10: QUALIDADE DO DADO. Apontar mais horas que a jornada indica erro de lançamento, hora extra não parametrizada ou duplicidade de ordem. Infla o IAP.
A11: IDF | B11: Divergência de escala | C11: Dias em que o turno de cadastro (ou o ciclo, no caso do folguista) e o turno inferido pela hora não coincidem | D11: Zero | E11: Diária | F11: Base Diária · col. V | G11: CONTROLE DA ESCALA. O turno de TODO empregado é apurado pela hora do apontamento, não pelo cadastro. Base atual: 226 dias divergentes, a maioria ADM apurado como A — revisar antes de usar o IAP para cobrança.
A13: AS 9 ABAS DA PASTA
A14: Leia-me | C14: Esta aba: definição dos indicadores, mapa da pasta e premissas assumidas.
A15: Parâmetros | C15: ÚNICO ponto de digitação. Jornadas por turno, meta, data de corte, tolerância, limites da inferência, de-para de escalas, regra de folga por escala e sequência de turnos do folguista.
A16: Cadastro | C16: CADASTRO COM VIGÊNCIA. Uma linha por empregado E por período. Colunas de entrada: escala, data de vigência e dia do ciclo no 1º dia da série. Mudou de escala? Acrescente uma linha nova, sem apagar a anterior.
A17: Dados | C17: Extração bruta do SAP (16 colunas, intocadas) + 3 colunas de apoio: Q = minuto de início, R = minuto de fim, S = DATA DO TURNO (reatribui a madrugada ao dia de entrada).
A18: Base Diária | C18: TABELA FATO. 1 linha = 1 empregado × 1 dia. Única fonte de verdade. W e X contam o ciclo de trabalho/folga; Z e AA medem a ausência seguida; Y classifica o dia; AB aponta a linha do Cadastro vigente naquela data.
A19: Painel Centro | C19: Consolidado por centro de trabalho, com semáforo contra a meta.
A20: Painel Empregado | C20: Consolidado por empregado, com filtro por centro de trabalho.
A21: Matriz Diária | C21: Visão matricial: em cima, cada empregado dia a dia (com filtro por centro); embaixo, o IAP ponderado de cada centro no mesmo eixo de datas, mais GERAL e META.
A24: PREMISSAS E LIMITAÇÕES ASSUMIDAS
A25: • Jornada de referência (Parâmetros!E6:E9): A = 7,58 h · B = 7,67 h · C = 6,67 h · ADM = 8,80 h. Valores informados pelo usuário nesta planilha.
A26: • Escalas 6x1 e FF 6x1 têm jornada FIXA pelo contrato, não inferida: 07:00 às 16:48 (8,80 h líquidas) de segunda a sexta, e 07:00 às 15:20 (7,33 h) no sábado e no domingo. Linhas 9 e 10 de Parâmetros.
A27: • ESCALA 5x2: jornada fixa de 07:00 às 16:48 (8,80 h líquidas) de segunda a sexta. Sábado e domingo são folga por calendário e não têm jornada de referência — apontamento no fim de semana é marcado como "Folga trabalhada" e fica fora da apuração, por ser hora extra e não utilização de jornada programada.
A28: • O turno ADM foi REMOVIDO. Ele existia só para representar o 6x1 e obrigava a inferência a um desempate frágil pela hora de saída: quem encerrava antes das 15:35 virava turno A e ganhava divisor de 7,58 h em vez de 8,80 h. Com a jornada fixa isso deixou de existir.
A29: • REGRA DA DATA DO TURNO: todo apontamento iniciado antes da entrada do diurno (Parâmetros!E19, derivado de 07:00) é somado ao DIA DE ENTRADA da jornada, ou seja, ao dia anterior. Vale para qualquer escala.
A30: • Corte às 07:00 e não às 07:20: na base atual não existe NENHUM apontamento de turno C entre 07:00 e 07:19, enquanto há 350 apontamentos A/ADM nessa faixa. Cortar às 07:00 preserva os dois lados.
A31: • MUDANÇA DE ESCALA NO MEIO DO PERÍODO: registre uma linha nova no Cadastro com o mesmo Nº pessoal, a escala nova e a data de vigência. A linha antiga permanece e continua valendo para os dias anteriores. Sobrescrever a linha existente aplicaria a escala nova ao mês inteiro e corromperia o histórico.
A32: • HIERARQUIA DE APURAÇÃO DO TURNO: (1) sendo 6x1 ou FF 6x1, a jornada é a do contrato — não se olha a hora. (2) nas demais escalas, havendo apontamento o turno vem da hora do 1º registro: a partir de E18 (23:20) ou antes de E19 (07:00) = C; antes de E20 (15:00) = A; senão B. (3) sem apontamento, vale o cadastro.
A33: • A evidência prevalece sobre o cadastro e sobre o ciclo porque a escala real muda por troca, cobertura e hora extra. A coluna V registra toda divergência para tratativa.
A34: • Empregados em Férias ou Folguista não têm jornada de referência própria: em dias SEM apontamento ficam FORA da apuração. Havendo apontamento, o turno é inferido pela hora normalmente.
A35: • ESCALA FOLGUISTA: ciclo de 4 dias de trabalho (B, B, C, C) e 2 de folga. A posição no ciclo é contada pelos apontamentos, sem data-âncora.
... A53: • A Base Diária traz o vínculo nas colunas AC (Exceção do dia) e AD (Motivo), casadas por Nº pessoal + data. Isso cobre manualmente a lacuna do campo de motivo de ausência que não vem na extração do SAP.

Sheet Parâmetros
A1: PARÂMETROS DA APURAÇÃO
A2: Tudo que se digita nesta pasta está nesta aba. Células amarelas = entrada do usuário; as demais são calculadas.
A4: JORNADAS DE REFERÊNCIA
A5: Turno | B5: Entrada | C5: Saída | D5: Jornada bruta (h) | E5: Jornada líquida (h) | F5: Meta em horas
A6: A | B6: 0.29166667 | C6: 0.64930556 | D6: 8.58 | E6: 7.58 | F6: =$E6*$E$13 -> 6.064
A7: B | B7: 0.625 | C7: 0.98611111 | D7: 8.67 | E7: 7.67 | F7: =$E7*$E$13 -> 6.136
A8: C | B8: 0.97222222 | C8: 0.30555556 | D8: 7.67 | E8: 6.67 | F8: =$E8*$E$13 -> 5.336
A9: 6x1 | B9: 0.29166667 | C9: 0.7 | D9: 9.8 | E9: 8.8 | F9: =$E9*$E$13 -> 7.04
A10: 6x1 sáb/dom | B10: 0.29166667 | C10: 0.63888889 | D10: 8.33 | E10: 7.33 | F10: =$E10*$E$13 -> 5.864
A11: 5x2 | B11: 0.29166667 | C11: 0.7 | D11: 9.8 | E11: 8.8 | F11: =$E11*$E$13 -> 7.04
A12: PARÂMETROS DO INDICADOR
A13: Meta de apontamento | E13: 0.8
A14: Última data apurada | E14: 46318
A15: Tolerância de sobre-apontamento | E15: 1
A16: Dias sem apontamento para afastamento | E16: 30
A17: LIMITES DA INFERÊNCIA DE TURNO — derivados das jornadas acima, em minutos
A18: Entrada do turno C | E18: =HOUR($B$8)*60+MINUTE($B$8) -> 1400
A19: Entrada do diurno (corte da madrugada) | E19: =HOUR($B$6)*60+MINUTE($B$6) -> 420
A20: Entrada do turno B | E20: =HOUR($B$7)*60+MINUTE($B$7) -> 900
A23: Regra: para 6x1 e FF 6x1 a jornada é FIXA pelo contrato (07:00-16:48 de segunda a sexta e no domingo; 07:00-15:20 no sábado). Para as demais escalas o turno é deduzido da hora do 1º apontamento: a partir de E18 ou antes de E19 = C; antes de E20 = A; senão B.
A24: O turno ADM foi removido: ele existia apenas para representar o 6x1, que agora tem jornada própria e não depende de inferência.
A26: Escala no cadastro | B26: Turno de referência
A27: 6x1 | B27: 6x1
A28: A | B28: A
A29: B | B29: B
A30: C | B30: C
A31: FF 6x1 | B31: 6x1
A32: FF A | B32: A
A33: FF B | B33: B
A34: Folguista | B34: Folguista
A35: Férias | B35: Férias
A36: 5x2 | B36: 5x2
A37: REGRA DE FOLGA POR ESCALA
A38: Turno de referência | B38: Dias de trabalho | C38: Dias de folga | D38: Como a folga é identificada
A39: 6x1 | B39: 6 | C39: 1 | D39: Sábado e domingo sem apontamento são folga. Trabalha sábado OU domingo, nunca os dois. Falta de registro só existe de segunda a sexta
A40: A | B40: 5 | C40: 1 | D40: Após 5 dias seguidos com apontamento, o próximo dia sem apontamento é folga
A41: B | B41: 5 | C41: 1 | D41: Após 5 dias seguidos com apontamento, o próximo dia sem apontamento é folga
A42: C | B42: 5 | C42: 1 | D42: Após 5 dias seguidos com apontamento, o próximo dia sem apontamento é folga
A43: Folguista | B43: 4 | C43: 2 | D43: Após 4 dias seguidos com apontamento, os 2 dias seguintes sem apontamento são folga
A44: 5x2 | B44: 5 | C44: 2 | D44: Sábado e domingo são folga (regra de calendário). Falta de registro só existe de segunda a sexta
...

Sheet Cadastro
A1: CADASTRO DO EFETIVO DE MANUTENÇÃO · COM VIGÊNCIA
A2: Uma linha por empregado E por período de vigência. Mudou de escala ou de turno? Acrescente uma linha nova com a data em que a mudança passou a valer — não sobrescreva a anterior.
A4: Nº pessoal | B4: Empregado | C4: Centro de Trabalho | D4: Escala (cadastro) | E4: Vigente a partir de | F4: Dia do ciclo no 1º dia da série | G4: Turno de referência | H4: Entra na apuração? | I4: Chave (auxiliar)
A5: 9218 | B5: Adriano Donizete Bento Da Silva | C5: =IFERROR(VLOOKUP($A5,Dados!$A:$C,3,FALSE()),"NÃO INFORMADO") -> INS | D5: 6x1 | E5: 46237 | G5: 6x1 | H5: =IF(OR($G5="A",$G5="B",$G5="C",$G5="6x1",$G5="5x2",$G5="Folguista"),"Sim","Não") -> Sim | I5: =$A5&"|"&TEXT($E5,"yyyymmdd") -> 9218|yyyy0803
A6: 9218 | B6: Adriano Donizete Bento Da Silva | C6: =IFERROR(VLOOKUP($A6,Dados!$A:$C,3,FALSE()),"NÃO INFORMADO") -> INS | D6: A | E6: 46272 | G6: A | H6: =IF(OR($G6="A",$G6="B",$G6="C",$G6="6x1",$G6="5x2",$G6="Folguista"),"Sim","Não") -> Sim | I6: =$A6&"|"&TEXT($E6,"yyyymmdd") -> 9218|yyyy0907
A7: 9218 | B7: Adriano Donizete Bento Da Silva | C7: =IFERROR(VLOOKUP($A7,Dados!$A:$C,3,FALSE()),"NÃO INFORMADO") -> INS | D7: 6x1 | E7: 46273 | G7: 6x1 | H7: =IF(OR($G7="A",$G7="B",$G7="C",$G7="6x1",$G7="5x2",$G7="Folguista"),"Sim","Não") -> Sim | I7: =$A7&"|"&TEXT($E7,"yyyymmdd") -> 9218|yyyy0908
A8: 9218 | B8: Adriano Donizete Bento Da Silva | C8: =IFERROR(VLOOKUP($A8,Dados!$A:$C,3,FALSE()),"NÃO INFORMADO") -> INS | D8: Férias | E8: 46279 | G8: Férias | H8: =IF(OR($G8="A",$G8="B",$G8="C",$G8="6x1",$G8="5x2",$G8="Folguista"),"Sim","Não") -> Não | I8: =$A8&"|"&TEXT($E8,"yyyymmdd") -> 9218|yyyy0914
A9: 9218 | B9: Adriano Donizete Bento Da Silva | C9: =IFERROR(VLOOKUP($A9,Dados!$A:$C,3,FALSE()),"NÃO INFORMADO") -> INS | D9: 6x1 | E9: 46309 | G9: 6x1 | H9: =IF(OR($G9="A",$G9="B",$G9="C",$G9="6x1",$G9="5x2",$G9="Folguista"),"Sim","Não") -> Sim | I9: =$A9&"|"&TEXT($E9,"yyyymmdd") -> 9218|yyyy1014
A10: 9218 | B10: Adriano Donizete Bento Da Silva | C10: =IFERROR(VLOOKUP($A10,Dados!$A:$C,3,FALSE()),"NÃO INFORMADO") -> INS | D10: A | E10: 46316 | G10: A | H10: =IF(OR($G10="A",$G10="B",$G10="C",$G10="6x1",$G10="5x2",$G10="Folguista"),"Sim","Não") -> Sim | I10: =$A10&"|"&TEXT($E10,"yyyymmdd") -> 9218|yyyy1021
A11: 11352 | B11: Aguinaldo Jose Gomes Rodrigues | C11: =IFERROR(VLOOKUP($A11,Dados!$A:$C,3,FALSE()),"NÃO INFORMADO") -> MEC | D11: A | E11: 46237 | F11: 1 | G11: A | H11: =IF(OR($G11="A",$G11="B",$G11="C",$G11="6x1",$G11="5x2",$G11="Folguista"),"Sim","Não") -> Sim | I11: =$A11&"|"&TEXT($E11,"yyyymmdd") -> 11352|yyyy0803
A12: 11352 | B12: Aguinaldo Jose Gomes Rodrigues | C12: =IFERROR(VLOOKUP($A12,Dados!$A:$C,3,FALSE()),"NÃO INFORMADO") -> MEC | D12: 6x1 | E12: 46265 | G12: 6x1 | H12: =IF(OR($G12="A",$G12="B",$G12="C",$G12="6x1",$G12="5x2",$G12="Folguista"),"Sim","Não") -> Sim | I12: =$A12&"|"&TEXT($E12,"yyyymmdd") -> 11352|yyyy0831
A13: 11352 | B13: Aguinaldo Jose Gomes Rodrigues | C13: =IFERROR(VLOOKUP($A13,Dados!$A:$C,3,FALSE()),"NÃO INFORMADO") -> MEC | D13: A | E13: 46307 | G13: A | H13: =IF(OR($G13="A",$G13="B",$G13="C",$G13="6x1",$G13="5x2",$G13="Folguista"),"Sim","Não") -> Sim | I13: =$A13&"|"&TEXT($E13,"yyyymmdd") -> 11352|yyyy1012
A14: 11352 | B14: Aguinaldo Jose Gomes Rodrigues | C14: =IFERROR(VLOOKUP($A14,Dados!$A:$C,3,FALSE()),"NÃO INFORMADO") -> MEC | D14: 6x1 | E14: 46308 | G14: 6x1 | H14: =IF(OR($G14="A",$G14="B",$G14="C",$G14="6x1",$G14="5x2",$G14="Folguista"),"Sim","Não") -> Sim | I14: =$A14&"|"&TEXT($E14,"yyyymmdd") -> 11352|yyyy1013
A15: 56222 | B15: Alexandre Bueno Júnior | C15: =IFERROR(VLOOKUP($A15,Dados!$A:$C,3,FALSE()),"NÃO INFORMADO") -> AUT | D15: Férias | E15: 46237 | G15: Férias | H15: =IF(OR($G15="A",$G15="B",$G15="C",$G15="6x1",$G15="5x2",$G15="Folguista"),"Sim","Não") -> Não | I15: =$A15&"|"&TEXT($E15,"yyyymmdd") -> 56222|yyyy0803
A16: 56222 | B16: Alexandre Bueno Júnior | C16: =IFERROR(VLOOKUP($A16,Dados!$A:$C,3,FALSE()),"NÃO INFORMADO") -> AUT | D16: 6x1 | E16: 46244 | G16: 6x1 | H16: =IF(OR($G16="A",$G16="B",$G16="C",$G16="6x1",$G16="5x2",$G16="Folguista"),"Sim","Não") -> Sim | I16: =$A16&"|"&TEXT($E16,"yyyymmdd") -> 56222|yyyy0810
A17: 56222 | B17: Alexandre Bueno Júnior | C17: =IFERROR(VLOOKUP($A17,Dados!$A:$C,3,FALSE()),"NÃO INFORMADO") -> AUT | D17: Férias | E17: 46307 | G17: Férias | H17: =IF(OR($G17="A",$G17="B",$G17="C",$G17="6x1",$G17="5x2",$G17="Folguista"),"Sim","Não") -> Não | I17: =$A17&"|"&TEXT($E17,"yyyymmdd") -> 56222|yyyy1012
A18: 54161 | B18: Alexandre Miranda Damaceno | C18: =IFERROR(VLOOKUP($A18,Dados!$A:$C,3,FALSE()),"NÃO INFORMADO") -> ELE | D18: B | E18: 46237 | F18: 2 | G18: B | H18: =IF(OR($G18="A",$G18="B",$G18="C",$G18="6x1",$G18="5x2",$G18="Folguista"),"Sim","Não") -> Sim | I18: =$A18&"|"&TEXT($E18,"yyyymmdd") -> 54161|yyyy0803
A19: 11950 | B19: Andre Luiz Bolonha | C19: =IFERROR(VLOOKUP($A19,Dados!$A:$C,3,FALSE()),"NÃO INFORMADO") -> CAL | D19: B | E19: 46237 | F19: 1 | G19: B | H19: =IF(OR($G19="A",$G19="B",$G19="C",$G19="6x1",$G19="5x2",$G19="Folguista"),"Sim","Não") -> Sim | I19: =$A19&"|"&TEXT($E19,"yyyymmdd") -> 11950|yyyy0803
A20: 52351 | B20: Antonio Dos Anjos Gomes | C20: =IFERROR(VLOOKUP($A20,Dados!$A:$C,3,FALSE()),"NÃO INFORMADO") -> LUB | D20: 6x1 | E20: 46237 | G20: 6x1 | H20: =IF(OR($G20="A",$G20="B",$G20="C",$G20="6x1",$G20="5x2",$G20="Folguista"),"Sim","Não") -> Sim | I20: =$A20&"|"&TEXT($E20,"yyyymmdd") -> 52351|yyyy0803
A21: 52351 | B21: Antonio Dos Anjos Gomes | C21: =IFERROR(VLOOKUP($A21,Dados!$A:$C,3,FALSE()),"NÃO INFORMADO") -> LUB | D21: Férias | E21: 46251 | G21: Férias | H21: =IF(OR($G21="A",$G21="B",$G21="C",$G21="6x1",$G21="5x2",$G21="Folguista"),"Sim","Não") -> Não | I21: =$A21&"|"&TEXT($E21,"yyyymmdd") -> 52351|yyyy0817
A22: 52351 | B22: Antonio Dos Anjos Gomes | C22: =IFERROR(VLOOKUP($A22,Dados!$A:$C,3,FALSE()),"NÃO INFORMADO") -> LUB | D22: 6x1 | E22: 46281 | G22: 6x1 | H22: =IF(OR($G22="A",$G22="B",$G22="C",$G22="6x1",$G22="5x2",$G22="Folguista"),"Sim","Não") -> Sim | I22: =$A22&"|"&TEXT($E22,"yyyymmdd") -> 52351|yyyy0916
A23: 52351 | B23: Antonio Dos Anjos Gomes | C23: =IFERROR(VLOOKUP($A23,Dados!$A:$C,3,FALSE()),"NÃO INFORMADO") -> LUB | D23: A | E23: 46307 | G23: A | H23: =IF(OR($G23="A",$G23="B",$G23="C",$G23="6x1",$G23="5x2",$G23="Folguista"),"Sim","Não") -> Sim | I23: =$A23&"|"&TEXT($E23,"yyyymmdd") -> 52351|yyyy1012
A24: 52351 | B24: Antonio Dos Anjos Gomes | C24: =IFERROR(VLOOKUP($A24,Dados!$A:$C,3,FALSE()),"NÃO INFORMADO") -> LUB | D24: 6x1 | E24: 46308 | G24: 6x1 | H24: =IF(OR($G24="A",$G24="B",$G24="C",$G24="6x1",$G24="5x2",$G24="Folguista"),"Sim","Não") -> Sim | I24: =$A24&"|"&TEXT($E24,"yyyymmdd") -> 52351|yyyy1013
A25: 53726 | B25: Carlos Roberto Rodrigues | C25: =IFERROR(VLOOKUP($A25,Dados!$A:$C,3,FALSE()),"NÃO INFORMADO") -> PED | D25: 6x1 | E25: 46237 | G25: 6x1 | H25: =IF(OR($G25="A",$G25="B",$G25="C",$G25="6x1",$G25="5x2",$G25="Folguista"),"Sim","Não") -> Sim | I25: =$A25&"|"&TEXT($E25,"yyyymmdd") -> 53726|yyyy0803
A26: 53726 | B26: Carlos Roberto Rodrigues | C26: =IFERROR(VLOOKUP($A26,Dados!$A:$C,3,FALSE()),"NÃO INFORMADO") -> PED | D26: A | E26: 46307 | G26: A | H26: =IF(OR($G26="A",$G26="B",$G26="C",$G26="6x1",$G26="5x2",$G26="Folguista"),"Sim","Não") -> Sim | I26: =$A26&"|"&TEXT($E26,"yyyymmdd") -> 53726|yyyy1012
A27: 53726 | B27: Carlos Roberto Rodrigues | C27: =IFERROR(VLOOKUP($A27,Dados!$A:$C,3,FALSE()),"NÃO INFORMADO") -> PED | D27: 6x1 | E27: 46308 | G27: 6x1 | H27: =IF(OR($G27="A",$G27="B",$G27="C",$G27="6x1",$G27="5x2",$G27="Folguista"),"Sim","Não") -> Sim | I27: =$A27&"|"&TEXT($E27,"yyyymmdd") -> 53726|yyyy1013
A28: 56030 | B28: Cícero Roberto de oliveira | C28: =IFERROR(VLOOKUP($A28,Dados!$A:$C,3,FALSE()),"NÃO INFORMADO") -> PED | D28: 6x1 | E28: 46237 | G28: 6x1 | H28: =IF(OR($G28="A",$G28="B",$G28="C",$G28="6x1",$G28="5x2",$G28="Folguista"),"Sim","Não") -> Sim | I28: =$A28&"|"&TEXT($E28,"yyyymmdd") -> 56030|yyyy0803
A29: 56030 | B29: Cícero Roberto de oliveira | C29: =IFERROR(VLOOKUP($A29,Dados!$A:$C,3,FALSE()),"NÃO INFORMADO") -> PED | D29: A | E29: 46272 | G29: A | H29: =IF(OR($G29="A",$G29="B",$G29="C",$G29="6x1",$G29="5x2",$G29="Folguista"),"Sim","Não") -> Sim | I29: =$A29&"|"&TEXT($E29,"yyyymmdd") -> 56030|yyyy0907
A30: 56030 | B30: Cícero Roberto de oliveira | C30: =IFERROR(VLOOKUP($A30,Dados!$A:$C,3,FALSE()),"NÃO INFORMADO") -> PED | D30: 6x1 | E30: 46273 | G30: 6x1 | H30: =IF(OR($G30="A",$G30="B",$G30="C",$G30="6x1",$G30="5x2",$G30="Folguista"),"Sim","Não") -> Sim | I30: =$A30&"|"&TEXT($E30,"yyyymmdd") -> 56030|yyyy0908
A31: 56030 | B31: Cícero Roberto de oliveira | C31: =IFERROR(VLOOKUP($A31,Dados!$A:$C,3,FALSE()),"NÃO INFORMADO") -> PED | D31: A | E31: 46307 | G31: A | H31: =IF(OR($G31="A",$G31="B",$G31="C",$G31="6x1",$G31="5x2",$G31="Folguista"),"Sim","Não") -> Sim | I31: =$A31&"|"&TEXT($E31,"yyyymmdd") -> 56030|yyyy1012
... A37: 11229 | B37: Cristiano Henrique Soares De Jesus | C37: =IFERROR(VLOOKUP($A37,Dados!$A:$C,3,FALSE()),"NÃO INFORMADO") -> CAL | D37: 6x1 | E37: 46308 | G37: 6x1 | H37: =IF(OR($G37="A",$G37="B",$G37="C",$G37="6x1",$G37="5x2",$G37="Folguista"),"Sim","Não") -> Sim | I37: =$A37&"|"&TEXT($E37,"yyyymmdd") -> 11229|yyyy1013
A38: 54611 | B38: Damiao Washington da Silva Oliveira | C38: =IFERROR(VLOOKUP($A38,Dados!$A:$C,3,FALSE()),"NÃO INFORMADO") -> CAL | D38: B | E38: 46237 | F38: 1 | G38: B | H38: =IF(OR($G38="A",$G38="B",$G38="C",$G38="6x1",$G38="5x2",$G38="Folguista"),"Sim","Não") -> Sim | I38: =$A38&"|"&TEXT($E38,"yyyymmdd") -> 54611|yyyy0803
A39: 53512 | B39: Daniel Henrique De Azevedo | C39: =IFERROR(VLOOKUP($A39,Dados!$A:$C,3,FALSE()),"NÃO INFORMADO") -> AUT | D39: 6x1 | E39: 46237 | G39: 6x1 | H39: =IF(OR($G39="A",$G39="B",$G39="C",$G39="6x1",$G39="5x2",$G39="Folguista"),"Sim","Não") -> Sim | I39: =$A39&"|"&TEXT($E39,"yyyymmdd") -> 53512|yyyy0803
A40: 53512 | B40: Daniel Henrique De Azevedo | C40: =IFERROR(VLOOKUP($A40,Dados!$A:$C,3,FALSE()),"NÃO INFORMADO") -> AUT | D40: A | E40: 46307 | G40: A | H40: =IF(OR($G40="A",$G40="B",$G40="C",$G40="6x1",$G40="5x2",$G40="Folguista"),"Sim","Não") -> Sim | I40: =$A40&"|"&TEXT($E40,"yyyymmdd") -> 53512|yyyy1012
A41: 53512 | B41: Daniel Henrique De Azevedo | C41: =IFERROR(VLOOKUP($A41,Dados!$A:$C,3,FALSE()),"NÃO INFORMADO") -> AUT | D41: 6x1 | E41: 46308 | G41: 6x1 | H41: =IF(OR($G41="A",$G41="B",$G41="C",$G41="6x1",$G41="5x2",$G41="Folguista"),"Sim","Não") -> Sim | I41: =$A41&"|"&TEXT($E41,"yyyymmdd") -> 53512|yyyy1013
A42: 56784 | B42: Danilo Elimar Campos | C42: =IFERROR(VLOOKUP($A42,Dados!$A:$C,3,FALSE()),"NÃO INFORMADO") -> USI | D42: C | E42: 46237 | F42: 4 | G42: C | H42: =IF(OR($G42="A",$G42="B",$G42="C",$G42="6x1",$G42="5x2",$G42="Folguista"),"Sim","Não") -> Sim | I42: =$A42&"|"&TEXT($E42,"yyyymmdd") -> 56784|yyyy0803
A43: 56784 | B43: Danilo Elimar Campos | C43: =IFERROR(VLOOKUP($A43,Dados!$A:$C,3,FALSE()),"NÃO INFORMADO") -> USI | D43: B | E43: 46309 | G43: B | H43: =IF(OR($G43="A",$G43="B",$G43="C",$G43="6x1",$G43="5x2",$G43="Folguista"),"Sim","Não") -> Sim | I43: =$A43&"|"&TEXT($E43,"yyyymmdd") -> 56784|yyyy1014
A44: 56855 | B44: Divanil Batista Neponocena | C44: =IFERROR(VLOOKUP($A44,Dados!$A:$C,3,FALSE()),"NÃO INFORMADO") -> INS | D44: 6x1 | E44: 46237 | G44: 6x1 | H44: =IF(OR($G44="A",$G44="B",$G44="C",$G44="6x1",$G44="5x2",$G44="Folguista"),"Sim","Não") -> Sim | I44: =$A44&"|"&TEXT($E44,"yyyymmdd") -> 56855|yyyy0803
A45: 56855 | B45: Divanil Batista Neponocena | C45: =IFERROR(VLOOKUP($A45,Dados!$A:$C,3,FALSE()),"NÃO INFORMADO") -> INS | D45: A | E45: 46252 | G45: A | H45: =IF(OR($G45="A",$G45="B",$G45="C",$G45="6x1",$G45="5x2",$G45="Folguista"),"Sim","Não") -> Sim | I45: =$A45&"|"&TEXT($E45,"yyyymmdd") -> 56855|yyyy0818
A46: 56855 | B46: Divanil Batista Neponocena | C46: =IFERROR(VLOOKUP($A46,Dados!$A:$C,3,FALSE()),"NÃO INFORMADO") -> INS | D46: 6x1 | E46: 46253 | G46: 6x1 | H46: =IF(OR($G46="A",$G46="B",$G46="C",$G46="6x1",$G46="5x2",$G46="Folguista"),"Sim","Não") -> Sim | I46: =$A46&"|"&TEXT($E46,"yyyymmdd") -> 56855|yyyy0819
...

Sheet Exceções
A1: EXCEÇÕES DO DIA · ABONOS, FOLGAS E AFASTAMENTOS PONTUAIS
A2: Uma linha por empregado E por dia. Use para dias isolados que não seguem a escala do Cadastro (folga por troca de escala, abono, atestado, treinamento). NÃO use para mudança de escala ou turno — isso é vigência e vai no Cadastro.
A4: Nº pessoal | B4: Empregado | C4: Data | D4: Tipo | E4: Motivo / observação | F4: Chave (auxiliar) | H4: Tipos aceitos
A5: 53346 | B5: =IF($A5="","",IFERROR(VLOOKUP($A5,Dados!$A:$B,2,FALSE),"Nº NÃO ENCONTRADO")) -> Francinildo da Silva | C5: 46266 | D5: Treinamento | E5: O funcionario estava em treinamento | F5: =IF(OR($A5="",$C5=""),"",$A5&"|"&$C5) -> 53346|46266 | H5: Folga
A6: 55628 | B6: =IF($A6="","",IFERROR(VLOOKUP($A6,Dados!$A:$B,2,FALSE),"Nº NÃO ENCONTRADO")) -> Marcelo Magnani dos Santos de Melo | C6: 46266 | D6: Treinamento | E6: O funcionario estava em treinamento | F6: =IF(OR($A6="",$C6=""),"",$A6&"|"&$C6) -> 55628|46266 | H6: Abono
A7: 11918 | B7: =IF($A7="","",IFERROR(VLOOKUP($A7,Dados!$A:$B,2,FALSE),"Nº NÃO ENCONTRADO")) -> Jesuino Goncalves Pereira Neto | C7: 46272 | D7: Falta | E7: Não veio no feriado | F7: =IF(OR($A7="",$C7=""),"",$A7&"|"&$C7) -> 11918|46272 | H7: Atestado
A8: 52484 | B8: =IF($A8="","",IFERROR(VLOOKUP($A8,Dados!$A:$B,2,FALSE),"Nº NÃO ENCONTRADO")) -> Jose Marcos de Oliveira | C8: 46272 | D8: Falta | E8: Não veio no feriado | F8: =IF(OR($A8="",$C8=""),"",$A8&"|"&$C8) -> 52484|46272 | H8: Treinamento
A9: 11415 | B9: =IF($A9="","",IFERROR(VLOOKUP($A9,Dados!$A:$B,2,FALSE),"Nº NÃO ENCONTRADO")) -> Jaime Martins da Silva | C9: 46273 | D9: Treinamento | E9: O funcionario estava em treinamento | F9: =IF(OR($A9="",$C9=""),"",$A9&"|"&$C9) -> 11415|46273 | H9: Falta
A10: 53346 | B10: =IF($A10="","",IFERROR(VLOOKUP($A10,Dados!$A:$B,2,FALSE),"Nº NÃO ENCONTRADO")) -> Francinildo da Silva | C10: 46274 | D10: Treinamento | E10: O funcionario estava em treinamento | F10: =IF(OR($A10="",$C10=""),"",$A10&"|"&$C10) -> 53346|46274
A11: 55628 | B11: =IF($A11="","",IFERROR(VLOOKUP($A11,Dados!$A:$B,2,FALSE),"Nº NÃO ENCONTRADO")) -> Marcelo Magnani dos Santos de Melo | C11: 46274 | D11: Treinamento | E11: O funcionario estava em treinamento | F11: =IF(OR($A11="",$C11=""),"",$A11&"|"&$C11) -> 55628|46274
A12: 55564 | B12: =IF($A12="","",IFERROR(VLOOKUP($A12,Dados!$A:$B,2,FALSE),"Nº NÃO ENCONTRADO")) -> Paulo Ricardo da Mota Oliveira | C12: 46275 | D12: Falta | E12: Dispensa para ir no INSS | F12: =IF(OR($A12="",$C12=""),"",$A12&"|"&$C12) -> 55564|46275
A13: 55554 | B13: =IF($A13="","",IFERROR(VLOOKUP($A13,Dados!$A:$B,2,FALSE),"Nº NÃO ENCONTRADO")) -> Paulo Henrique Santana | C13: 46275 | D13: Falta | E13: O funcionario foi ao medico | F13: =IF(OR($A13="",$C13=""),"",$A13&"|"&$C13) -> 55554|46275
A14: 12291 | B14: =IF($A14="","",IFERROR(VLOOKUP($A14,Dados!$A:$B,2,FALSE),"Nº NÃO ENCONTRADO")) -> Osmar Marin de Oliveira | C14: 46275 | D14: Treinamento | E14: O funcionario estava em treinamento | F14: =IF(OR($A14="",$C14=""),"",$A14&"|"&$C14) -> 12291|46275
A15: 55628 | B15: =IF($A15="","",IFERROR(VLOOKUP($A15,Dados!$A:$B,2,FALSE),"Nº NÃO ENCONTRADO")) -> Marcelo Magnani dos Santos de Melo | C15: 46276 | D15: Atestado | E15: O funcionario estava de atestado | F15: =IF(OR($A15="",$C15=""),"",$A15&"|"&$C15) -> 55628|46276
A16: 56784 | B16: =IF($A16="","",IFERROR(VLOOKUP($A16,Dados!$A:$B,2,FALSE),"Nº NÃO ENCONTRADO")) -> Danilo Elimar Campos | C16: 46278 | D16: Folga | E16: Folga de escala | F16: =IF(OR($A16="",$C16=""),"",$A16&"|"&$C16) -> 56784|46278
A17: 11352 | B17: =IF($A17="","",IFERROR(VLOOKUP($A17,Dados!$A:$B,2,FALSE),"Nº NÃO ENCONTRADO")) -> Aguinaldo Jose Gomes Rodrigues | C17: 46278 | D17: Folga | E17: Trocou dia para folga | F17: =IF(OR($A17="",$C17=""),"",$A17&"|"&$C17) -> 11352|46278
A18: 55618 | B18: =IF($A18="","",IFERROR(VLOOKUP($A18,Dados!$A:$B,2,FALSE),"Nº NÃO ENCONTRADO")) -> Jerson Santana de Souza | C18: 46279 | D18: Atestado | E18: O funcionario estava de atestado | F18: =IF(OR($A18="",$C18=""),"",$A18&"|"&$C18) -> 55618|46279
A19: 12291 | B19: =IF($A19="","",IFERROR(VLOOKUP($A19,Dados!$A:$B,2,FALSE),"Nº NÃO ENCONTRADO")) -> Osmar Marin de Oliveira | C19: 46281 | D19: Abono | E19: O funcionario ficou ajudando no munck | F19: =IF(OR($A19="",$C19=""),"",$A19&"|"&$C19) -> 12291|46281
A20: 54747 | B20: =IF($A20="","",IFERROR(VLOOKUP($A20,Dados!$A:$B,2,FALSE),"Nº NÃO ENCONTRADO")) -> Rafael Nicoluci Vieira | C20: 46282 | D20: Treinamento | E20: O funcionario estava em treinamento | F20: =IF(OR($A20="",$C20=""),"",$A20&"|"&$C20) -> 54747|46282
A21: 52351 | B21: =IF($A21="","",IFERROR(VLOOKUP($A21,Dados!$A:$B,2,FALSE),"Nº NÃO ENCONTRADO")) -> Antonio dos Anjos Gomes | C21: 46282 | D21: Treinamento | E21: O funcionario estava em treinamento | F21: =IF(OR($A21="",$C21=""),"",$A21&"|"&$C21) -> 52351|46282
... A89: 55564 | B89: =IF($A89="","",IFERROR(VLOOKUP($A89,Dados!$A:$B,2,FALSE),"Nº NÃO ENCONTRADO")) -> Paulo Ricardo da Mota Oliveira | C89: 46316 | D89: Atestado | E89: Atestado médico | F89: =IF(OR($A89="",$C89=""),"",$A89&"|"&$C89) -> 55564|46316
B90: =IF($A90="","",IFERROR(VLOOKUP($A90,Dados!$A:$B,2,FALSE),"Nº NÃO ENCONTRADO")) | F90: =IF(OR($A90="",$C90=""),"",$A90&"|"&$C90)
B91: =IF($A91="","",IFERROR(VLOOKUP($A91,Dados!$A:$B,2,FALSE),"Nº NÃO ENCONTRADO")) | F91: =IF(OR($A91="",$C91=""),"",$A91&"|"&$C91)
B92: =IF($A92="","",IFERROR(VLOOKUP($A92,Dados!$A:$B,2,FALSE),"Nº NÃO ENCONTRADO")) | F92: =IF(OR($A92="",$C92=""),"",$A92&"|"&$C92)
B93: =IF($A93="","",IFERROR(VLOOKUP($A93,Dados!$A:$B,2,FALSE),"Nº NÃO ENCONTRADO")) | F93: =IF(OR($A93="",$C93=""),"",$A93&"|"&$C93)
B94: =IF($A94="","",IFERROR(VLOOKUP($A94,Dados!$A:$B,2,FALSE),"Nº NÃO ENCONTRADO")) | F94: =IF(OR($A94="",$C94=""),"",$A94&"|"&$C94)
B95: =IF($A95="","",IFERROR(VLOOKUP($A95,Dados!$A:$B,2,FALSE),"Nº NÃO ENCONTRADO")) | F95: =IF(OR($A95="",$C95=""),"",$A95&"|"&$C95)
B96: =IF($A96="","",IFERROR(VLOOKUP($A96,Dados!$A:$B,2,FALSE),"Nº NÃO ENCONTRADO")) | F96: =IF(OR($A96="",$C96=""),"",$A96&"|"&$C96)
B97: =IF($A97="","",IFERROR(VLOOKUP($A97,Dados!$A:$B,2,FALSE),"Nº NÃO ENCONTRADO")) | F97: =IF(OR($A97="",$C97=""),"",$A97&"|"&$C97)
B98: =IF($A98="","",IFERROR(VLOOKUP($A98,Dados!$A:$B,2,FALSE),"Nº NÃO ENCONTRADO")) | F98: =IF(OR($A98="",$C98=""),"",$A98&"|"&$C98)
B99: =IF($A99="","",IFERROR(VLOOKUP($A99,Dados!$A:$B,2,FALSE),"Nº NÃO ENCONTRADO")) | F99: =IF(OR($A99="",$C99=""),"",$A99&"|"&$C99)
B100: =IF($A100="","",IFERROR(VLOOKUP($A100,Dados!$A:$B,2,FALSE),"Nº NÃO ENCONTRADO")) | F100: =IF(OR($A100="",$C100=""),"",$A100&"|"&$C100)
B101: =IF($A101="","",IFERROR(VLOOKUP($A101,Dados!$A:$B,2,FALSE),"Nº NÃO ENCONTRADO")) | F101: =IF(OR($A101="",$C101=""),"",$A101&"|"&$C101)
... B208: =IF($A208="","",IFERROR(VLOOKUP($A208,Dados!$A:$B,2,FALSE),"Nº NÃO ENCONTRADO")) | F208: =IF(OR($A208="",$C208=""),"",$A208&"|"&$C208)
F209: =IF(OR($A209="",$C209=""),"",$A209&"|"&$C209)
F210: =IF(OR($A210="",$C210=""),"",$A210&"|"&$C210)
F211: =IF(OR($A211="",$C211=""),"",$A211&"|"&$C211)

Sheet Dados
A1: Nº pessoal | B1: Empregado | C1: Loc.inst.(real) | D1: Data lçto. | E1: Trabalho real | F1: UnidTrabReal | G1: Dt.início execução | H1: Ordem | I1: Operação | J1: Hora início execução | K1: Hora fim execução | L1: Data do fim execução | M1: Tipo ordem | N1: Equipamento | O1: Criado por | P1: Criado em | Q1: Início (min) | R1: Fim (min) | S1: Data do turno
A2: 9218 | B2: Adriano Donizete Bento da Silva | C2: INS | D2: 46309 | E2: 4.78 | F2: H | G2: 46309 | H2: 40525714 | I2: 10 | J2: 07:14:24 | K2: 12:01:04 | L2: 46309 | M2: LICO | O2: SIGGAINT | P2: 46309 | Q2: =IFERROR(VALUE(LEFT($J2,2))*60+VALUE(MID($J2,4,2)),9999) -> 434 | R2: =IFERROR(VALUE(LEFT($K2,2))*60+VALUE(MID($K2,4,2)),"") -> 721 | S2: =IF($Q2<Parâmetros!$E$19,$G2-1,$G2) -> 46309
A3: 9218 | B3: Adriano Donizete Bento da Silva | C3: INS | D3: 46309 | E3: 1.51 | F3: H | G3: 46309 | H3: 40524093 | I3: 10 | J3: 13:04:10 | K3: 14:34:42 | L3: 46309 | M3: LICO | N3: 3007376 | O3: SIGGAINT | P3: 46309 | Q3: =IFERROR(VALUE(LEFT($J3,2))*60+VALUE(MID($J3,4,2)),9999) -> 784 | R3: =IFERROR(VALUE(LEFT($K3,2))*60+VALUE(MID($K3,4,2)),"") -> 874 | S3: =IF($Q3<Parâmetros!$E$19,$G3-1,$G3) -> 46309
A4: 9218 | B4: Adriano Donizete Bento da Silva | C4: INS | D4: 46309 | E4: 0.97 | F4: H | G4: 46309 | H4: 40523288 | I4: 10 | J4: 14:39:32 | K4: 15:37:29 | L4: 46309 | M4: LIPV | O4: SIGGAINT | P4: 46309 | Q4: =IFERROR(VALUE(LEFT($J4,2))*60+VALUE(MID($J4,4,2)),9999) -> 879 | R4: =IFERROR(VALUE(LEFT($K4,2))*60+VALUE(MID($K4,4,2)),"") -> 937 | S4: =IF($Q4<Parâmetros!$E$19,$G4-1,$G4) -> 46309
A5: 9218 | B5: Adriano Donizete Bento da Silva | C5: INS | D5: 46309 | E5: 1 | F5: H | G5: 46309 | H5: 40523287 | I5: 10 | J5: 15:38:42 | K5: 16:38:40 | L5: 46309 | M5: LIPV | O5: SIGGAINT | P5: 46309 | Q5: =IFERROR(VALUE(LEFT($J5,2))*60+VALUE(MID($J5,4,2)),9999) -> 938 | R5: =IFERROR(VALUE(LEFT($K5,2))*60+VALUE(MID($K5,4,2)),"") -> 998 | S5: =IF($Q5<Parâmetros!$E$19,$G5-1,$G5) -> 46309
A6: 9218 | B6: Adriano Donizete Bento da Silva | C6: INS | D6: 46310 | E6: 0.86 | F6: H | G6: 46310 | H6: 40523284 | I6: 10 | J6: 07:06:48 | K6: 07:58:29 | L6: 46310 | M6: LIPV | O6: SIGGAINT | P6: 46310 | Q6: =IFERROR(VALUE(LEFT($J6,2))*60+VALUE(MID($J6,4,2)),9999) -> 426 | R6: =IFERROR(VALUE(LEFT($K6,2))*60+VALUE(MID($K6,4,2)),"") -> 478 | S6: =IF($Q6<Parâmetros!$E$19,$G6-1,$G6) -> 46310
A7: 9218 | B7: Adriano Donizete Bento da Silva | C7: INS | D7: 46310 | E7: 0.98 | F7: H | G7: 46310 | H7: 40523285 | I7: 10 | J7: 08:00:05 | K7: 08:59:10 | L7: 46310 | M7: LIPV | O7: SIGGAINT | P7: 46310 | Q7: =IFERROR(VALUE(LEFT($J7,2))*60+VALUE(MID($J7,4,2)),9999) -> 480 | R7: =IFERROR(VALUE(LEFT($K7,2))*60+VALUE(MID($K7,4,2)),"") -> 539 | S7: =IF($Q7<Parâmetros!$E$19,$G7-1,$G7) -> 46310
A8: 9218 | B8: Adriano Donizete Bento da Silva | C8: INS | D8: 46310 | E8: 0.68 | F8: H | G8: 46310 | H8: 40523286 | I8: 10 | J8: 09:02:47 | K8: 09:43:28 | L8: 46310 | M8: LIPV | O8: SIGGAINT | P8: 46310 | Q8: =IFERROR(VALUE(LEFT($J8,2))*60+VALUE(MID($J8,4,2)),9999) -> 542 | R8: =IFERROR(VALUE(LEFT($K8,2))*60+VALUE(MID($K8,4,2)),"") -> 583 | S8: =IF($Q8<Parâmetros!$E$19,$G8-1,$G8) -> 46310
A9: 9218 | B9: Adriano Donizete Bento da Silva | C9: INS | D9: 46310 | E9: 0.25 | F9: H | G9: 46310 | H9: 40524093 | I9: 10 | J9: 09:45:09 | K9: 10:00:07 | L9: 46310 | M9: LICO | N9: 3007376 | O9: SIGGAINT | P9: 46310 | Q9: =IFERROR(VALUE(LEFT($J9,2))*60+VALUE(MID($J9,4,2)),9999) -> 585 | R9: =IFERROR(VALUE(LEFT($K9,2))*60+VALUE(MID($K9,4,2)),"") -> 600 | S9: =IF($Q9<Parâmetros!$E$19,$G9-1,$G9) -> 46310
A10: 9218 | B10: Adriano Donizete Bento da Silva | C10: INS | D10: 46310 | E10: 2.11 | F10: H | G10: 46310 | H10: 40525708 | I10: 10 | J10: 10:00:26 | K10: 12:07:14 | L10: 46310 | M10: LICO | O10: SIGGAINT | P10: 46310 | Q10: =IFERROR(VALUE(LEFT($J10,2))*60+VALUE(MID($J10,4,2)),9999) -> 600 | R10: =IFERROR(VALUE(LEFT($K10,2))*60+VALUE(MID($K10,4,2)),"") -> 727 | S10: =IF($Q10<Parâmetros!$E$19,$G10-1,$G10) -> 46310
A11: 9218 | B11: Adriano Donizete Bento da Silva | C11: INS | D11: 46310 | E11: 3.29 | F11: H | G11: 46310 | H11: 40524093 | I11: 10 | J11: 13:01:54 | K11: 16:19:32 | L11: 46310 | M11: LICO | N11: 3007376 | O11: SIGGAINT | P11: 46310 | Q11: =IFERROR(VALUE(LEFT($J11,2))*60+VALUE(MID($J11,4,2)),9999) -> 781 | R11: =IFERROR(VALUE(LEFT($K11,2))*60+VALUE(MID($K11,4,2)),"") -> 979 | S11: =IF($Q11<Parâmetros!$E$19,$G11-1,$G11) -> 46310
A12: 9218 | B12: Adriano Donizete Bento da Silva | C12: INS | D12: 46310 | E12: -3.29 | F12: H | G12: 46310 | H12: 40524093 | I12: 10 | J12: 13:01:54 | K12: 16:19:32 | L12: 46310 | M12: LICO | N12: 3007376 | O12: GF57085 | P12: 46311 | Q12: =IFERROR(VALUE(LEFT($J12,2))*60+VALUE(MID($J12,4,2)),9999) -> 781 | R12: =IFERROR(VALUE(LEFT($K12,2))*60+VALUE(MID($K12,4,2)),"") -> 979 | S12: =IF($Q12<Parâmetros!$E$19,$G12-1,$G12) -> 46310
A13: 9218 | B13: Adriano Donizete Bento da Silva | C13: INS | D13: 46310 | E13: 3.2 | F13: H | G13: 46310 | H13: 40526417 | I13: 10 | J13: 13:06:21 | K13: 16:18:30 | L13: 46310 | M13: LICO | O13: SIGGAINT | P13: 46310 | Q13: =IFERROR(VALUE(LEFT($J13,2))*60+VALUE(MID($J13,4,2)),9999) -> 786 | R13: =IFERROR(VALUE(LEFT($K13,2))*60+VALUE(MID($K13,4,2)),"") -> 978 | S13: =IF($Q13<Parâmetros!$E$19,$G13-1,$G13) -> 46310
A14: 9218 | B14: Adriano Donizete Bento da Silva | C14: INS | D14: 46311 | E14: 1.16 | F14: H | G14: 46311 | H14: 40524550 | I14: 10 | J14: 07:04:03 | K14: 08:13:38 | L14: 46311 | M14: LICO | O14: SIGGAINT | P14: 46311 | Q14: =IFERROR(VALUE(LEFT($J14,2))*60+VALUE(MID($J14,4,2)),9999) -> 424 | R14: =IFERROR(VALUE(LEFT($K14,2))*60+VALUE(MID($K14,4,2)),"") -> 493 | S14: =IF($Q14<Parâmetros!$E$19,$G14-1,$G14) -> 46311
A15: 9218 | B15: Adriano Donizete Bento da Silva | C15: INS | D15: 46311 | E15: 0.51 | F15: H | G15: 46311 | H15: 40526684 | I15: 10 | J15: 08:15:13 | K15: 08:45:49 | L15: 46311 | M15: LICO | N15: 3007196 | O15: SIGGAINT | P15: 46311 | Q15: =IFERROR(VALUE(LEFT($J15,2))*60+VALUE(MID($J15,4,2)),9999) -> 495 | R15: =IFERROR(VALUE(LEFT($K15,2))*60+VALUE(MID($K15,4,2)),"") -> 525 | S15: =IF($Q15<Parâmetros!$E$19,$G15-1,$G15) -> 46311
A16: 9218 | B16: Adriano Donizete Bento da Silva | C16: INS | D16: 46311 | E16: 1.71 | F16: H | G16: 46311 | H16: 40526686 | I16: 10 | J16: 08:47:13 | K16: 10:30:00 | L16: 46311 | M16: LICO | O16: SIGGAINT | P16: 46311 | Q16: =IFERROR(VALUE(LEFT($J16,2))*60+VALUE(MID($J16,4,2)),9999) -> 527 | R16: =IFERROR(VALUE(LEFT($K16,2))*60+VALUE(MID($K16,4,2)),"") -> 630 | S16: =IF($Q16<Parâmetros!$E$19,$G16-1,$G16) -> 46311
A17: 9218 | B17: Adriano Donizete Bento da Silva | C17: INS | D17: 46311 | E17: 0.3 | F17: H | G17: 46311 | H17: 40526689 | I17: 10 | J17: 10:31:13 | K17: 10:49:04 | L17: 46311 | M17: LICO | O17: SIGGAINT | P17: 46311 | Q17: =IFERROR(VALUE(LEFT($J17,2))*60+VALUE(MID($J17,4,2)),9999) -> 631 | R17: =IFERROR(VALUE(LEFT($K17,2))*60+VALUE(MID($K17,4,2)),"") -> 649 | S17: =IF($Q17<Parâmetros!$E$19,$G17-1,$G17) -> 46311
A18: 9218 | B18: Adriano Donizete Bento da Silva | C18: INS | D18: 46311 | E18: 0.22 | F18: H | G18: 46311 | H18: 40526691 | I18: 10 | J18: 10:50:19 | K18: 11:03:26 | L18: 46311 | M18: LICO | O18: SIGGAINT | P18: 46311 | Q18: =IFERROR(VALUE(LEFT($J18,2))*60+VALUE(MID($J18,4,2)),9999) -> 650 | R18: =IFERROR(VALUE(LEFT($K18,2))*60+VALUE(MID($K18,4,2)),"") -> 663 | S18: =IF($Q18<Parâmetros!$E$19,$G18-1,$G18) -> 46311
A19: 9218 | B19: Adriano Donizete Bento da Silva | C19: INS | D19: 46311 | E19: 0.68 | F19: H | G19: 46311 | H19: 40526417 | I19: 10 | J19: 11:19:34 | K19: 12:00:14 | L19: 46311 | M19: LICO | O19: SIGGAINT | P19: 46311 | Q19: =IFERROR(VALUE(LEFT($J19,2))*60+VALUE(MID($J19,4,2)),9999) -> 679 | R19: =IFERROR(VALUE(LEFT($K19,2))*60+VALUE(MID($K19,4,2)),"") -> 720 | S19: =IF($Q19<Parâmetros!$E$19,$G19-1,$G19) -> 46311
A20: 9218 | B20: Adriano Donizete Bento da Silva | C20: INS | D20: 46312 | E20: 2.37 | F20: H | G20: 46311 | H20: 40526684 | I20: 10 | J20: 13:05:20 | K20: 15:27:31 | L20: 46311 | M20: LICO | N20: 3007196 | O20: SIGGAINT | P20: 46312 | Q20: =IFERROR(VALUE(LEFT($J20,2))*60+VALUE(MID($J20,4,2)),9999) -> 785 | R20: =IFERROR(VALUE(LEFT($K20,2))*60+VALUE(MID($K20,4,2)),"") -> 927 | S20: =IF($Q20<Parâmetros!$E$19,$G20-1,$G20) -> 46311
A21: 9218 | B21: Adriano Donizete Bento da Silva | C21: INS | D21: 46312 | E21: 18.05 | F21: H | G21: 46311 | H21: 40526684 | I21: 10 | J21: 13:07:00 | K21: 07:10:00 | L21: 46312 | M21: LICO | N21: 3007196 | O21: SIGGAINT | P21: 46312 | Q21: =IFERROR(VALUE(LEFT($J21,2))*60+VALUE(MID($J21,4,2)),9999) -> 787 | R21: =IFERROR(VALUE(LEFT($K21,2))*60+VALUE(MID($K21,4,2)),"") -> 430 | S21: =IF($Q21<Parâmetros!$E$19,$G21-1,$G21) -> 46311
A22: 9218 | B22: Adriano Donizete Bento da Silva | C22: INS | D22: 46312 | E22: -18.05 | F22: H | G22: 46311 | H22: 40526684 | I22: 10 | J22: 13:07:00 | K22: 07:10:00 | L22: 46312 | M22: LICO | N22: 3007196 | O22: SIGGAINT | P22: 46312 | Q22: =IFERROR(VALUE(LEFT($J22,2))*60+VALUE(MID($J22,4,2)),9999) -> 787 | R22: =IFERROR(VALUE(LEFT($K22,2))*60+VALUE(MID($K22,4,2)),"") -> 430 | S22: =IF($Q22<Parâmetros!$E$19,$G22-1,$G22) -> 46311
A23: 9218 | B23: Adriano Donizete Bento da Silva | C23: INS | D23: 46312 | E23: 0.75 | F23: H | G23: 46312 | H23: 40523292 | I23: 10 | J23: 07:17:30 | K23: 08:02:42 | L23: 46312 | M23: LIPV | O23: SIGGAINT | P23: 46312 | Q23: =IFERROR(VALUE(LEFT($J23,2))*60+VALUE(MID($J23,4,2)),9999) -> 437 | R23: =IFERROR(VALUE(LEFT($K23,2))*60+VALUE(MID($K23,4,2)),"") -> 482 | S23: =IF($Q23<Parâmetros!$E$19,$G23-1,$G23) -> 46312
A24: 9218 | B24: Adriano Donizete Bento da Silva | C24: INS | D24: 46312 | E24: 4.15 | F24: H | G24: 46312 | H24: 40527104 | I24: 10 | J24: 08:05:34 | K24: 12:14:23 | L24: 46312 | M24: LICO | O24: SIGGAINT | P24: 46312 | Q24: =IFERROR(VALUE(LEFT($J24,2))*60+VALUE(MID($J24,4,2)),9999) -> 485 | R24: =IFERROR(VALUE(LEFT($K24,2))*60+VALUE(MID($K24,4,2)),"") -> 734 | S24: =IF($Q24<Parâmetros!$E$19,$G24-1,$G24) -> 46312
A25: 9218 | B25: Adriano Donizete Bento da Silva | C25: INS | D25: 46314 | E25: 2.05 | F25: H | G25: 46312 | H25: 40527117 | I25: 10 | J25: 13:19:20 | K25: 15:22:11 | L25: 46312 | M25: LICO | N25: 3002696 | O25: SIGGAINT | P25: 46314 | Q25: =IFERROR(VALUE(LEFT($J25,2))*60+VALUE(MID($J25,4,2)),9999) -> 799 | R25: =IFERROR(VALUE(LEFT($K25,2))*60+VALUE(MID($K25,4,2)),"") -> 922 | S25: =IF($Q25<Parâmetros!$E$19,$G25-1,$G25) -> 46312
A26: 9218 | B26: Adriano Donizete Bento da Silva | C26: INS | D26: 46314 | E26: 0.55 | F26: H | G26: 46314 | H26: 40527666 | I26: 10 | J26: 07:10:36 | K26: 07:43:46 | L26: 46314 | M26: LICO | N26: 3004222 | O26: SIGGAINT | P26: 46314 | Q26: =IFERROR(VALUE(LEFT($J26,2))*60+VALUE(MID($J26,4,2)),9999) -> 430 | R26: =IFERROR(VALUE(LEFT($K26,2))*60+VALUE(MID($K26,4,2)),"") -> 463 | S26: =IF($Q26<Parâmetros!$E$19,$G26-1,$G26) -> 46314
A27: 9218 | B27: Adriano Donizete Bento da Silva | C27: INS | D27: 46314 | E27: 0.82 | F27: H | G27: 46314 | H27: 40527666 | I27: 10 | J27: 07:48:29 | K27: 08:37:41 | L27: 46314 | M27: LICO | N27: 3004222 | O27: SIGGAINT | P27: 46314 | Q27: =IFERROR(VALUE(LEFT($J27,2))*60+VALUE(MID($J27,4,2)),9999) -> 468 | R27: =IFERROR(VALUE(LEFT($K27,2))*60+VALUE(MID($K27,4,2)),"") -> 517 | S27: =IF($Q27<Parâmetros!$E$19,$G27-1,$G27) -> 46314
A28: 9218 | B28: Adriano Donizete Bento da Silva | C28: INS | D28: 46314 | E28: 3.37 | F28: H | G28: 46314 | H28: 40527667 | I28: 10 | J28: 08:38:08 | K28: 12:00:27 | L28: 46314 | M28: LICO | O28: SIGGAINT | P28: 46314 | Q28: =IFERROR(VALUE(LEFT($J28,2))*60+VALUE(MID($J28,4,2)),9999) -> 518 | R28: =IFERROR(VALUE(LEFT($K28,2))*60+VALUE(MID($K28,4,2)),"") -> 720 | S28: =IF($Q28<Parâmetros!$E$19,$G28-1,$G28) -> 46314
A29: 9218 | B29: Adriano Donizete Bento da Silva | C29: INS | D29: 46314 | E29: 0.4 | F29: H | G29: 46314 | H29: 40525991 | I29: 10 | J29: 13:04:51 | K29: 13:28:44 | L29: 46314 | M29: LIPV | N29: 3004490 | O29: SIGGAINT | P29: 46314 | Q29: =IFERROR(VALUE(LEFT($J29,2))*60+VALUE(MID($J29,4,2)),9999) -> 784 | R29: =IFERROR(VALUE(LEFT($K29,2))*60+VALUE(MID($K29,4,2)),"") -> 808 | S29: =IF($Q29<Parâmetros!$E$19,$G29-1,$G29) -> 46314
A30: 9218 | B30: Adriano Donizete Bento da Silva | C30: INS | D30: 46314 | E30: 0.56 | F30: H | G30: 46314 | H30: 40525991 | I30: 10 | J30: 13:35:21 | K30: 14:08:50 | L30: 46314 | M30: LIPV | N30: 3004490 | O30: SIGGAINT | P30: 46314 | Q30: =IFERROR(VALUE(LEFT($J30,2))*60+VALUE(MID($J30,4,2)),9999) -> 815 | R30: =IFERROR(VALUE(LEFT($K30,2))*60+VALUE(MID($K30,4,2)),"") -> 848 | S30: =IF($Q30<Parâmetros!$E$19,$G30-1,$G30) -> 46314
A31: 9218 | B31: Adriano Donizete Bento da Silva | C31: INS | D31: 46314 | E31: 0.47 | F31: H | G31: 46314 | H31: 40525990 | I31: 10 | J31: 14:09:17 | K31: 14:37:40 | L31: 46314 | M31: LIPV | N31: 3006716 | O31: SIGGAINT | P31: 46314 | Q31: =IFERROR(VALUE(LEFT($J31,2))*60+VALUE(MID($J31,4,2)),9999) -> 849 | R31: =IFERROR(VALUE(LEFT($K31,2))*60+VALUE(MID($K31,4,2)),"") -> 877 | S31: =IF($Q31<Parâmetros!$E$19,$G31-1,$G31) -> 46314
A32: 9218 | B32: Adriano Donizete Bento da Silva | C32: INS | D32: 46314 | E32: 0.51 | F32: H | G32: 46314 | H32: 40525992 | I32: 10 | J32: 14:38:05 | K32: 15:08:49 | L32: 46314 | M32: LIPV | N32: 3010797 | O32: SIGGAINT | P32: 46314 | Q32: =IFERROR(VALUE(LEFT($J32,2))*60+VALUE(MID($J32,4,2)),9999) -> 878 | R32: =IFERROR(VALUE(LEFT($K32,2))*60+VALUE(MID($K32,4,2)),"") -> 908 | S32: =IF($Q32<Parâmetros!$E$19,$G32-1,$G32) -> 46314
A33: 9218 | B33: Adriano Donizete Bento da Silva | C33: INS | D33: 46314 | E33: 0.45 | F33: H | G33: 46314 | H33: 40525993 | I33: 10 | J33: 15:10:19 | K33: 15:37:03 | L33: 46314 | M33: LIPV | N33: 3004491 | O33: SIGGAINT | P33: 46314 | Q33: =IFERROR(VALUE(LEFT($J33,2))*60+VALUE(MID($J33,4,2)),9999) -> 910 | R33: =IFERROR(VALUE(LEFT($K33,2))*60+VALUE(MID($K33,4,2)),"") -> 937 | S33: =IF($Q33<Parâmetros!$E$19,$G33-1,$G33) -> 46314
A34: 9218 | B34: Adriano Donizete Bento da Silva | C34: INS | D34: 46314 | E34: 0.89 | F34: H | G34: 46314 | H34: 40525994 | I34: 10 | J34: 15:37:29 | K34: 16:30:51 | L34: 46314 | M34: LIPV | N34: 3004492 | O34: SIGGAINT | P34: 46314 | Q34: =IFERROR(VALUE(LEFT($J34,2))*60+VALUE(MID($J34,4,2)),9999) -> 937 | R34: =IFERROR(VALUE(LEFT($K34,2))*60+VALUE(MID($K34,4,2)),"") -> 990 | S34: =IF($Q34<Parâmetros!$E$19,$G34-1,$G34) -> 46314
A35: 9218 | B35: Adriano Donizete Bento da Silva | C35: INS | D35: 46316 | E35: 0.73 | F35: H | G35: 46316 | H35: 40525995 | I35: 10 | J35: 07:12:05 | K35: 07:55:54 | L35: 46316 | M35: LIPV | N35: 3007941 | O35: SIGGAINT | P35: 46316 | Q35: =IFERROR(VALUE(LEFT($J35,2))*60+VALUE(MID($J35,4,2)),9999) -> 432 | R35: =IFERROR(VALUE(LEFT($K35,2))*60+VALUE(MID($K35,4,2)),"") -> 475 | S35: =IF($Q35<Parâmetros!$E$19,$G35-1,$G35) -> 46316
A36: 9218 | B36: Adriano Donizete Bento da Silva | C36: INS | D36: 46316 | E36: 0.81 | F36: H | G36: 46316 | H36: 40525996 | I36: 10 | J36: 07:56:20 | K36: 08:45:12 | L36: 46316 | M36: LIPV | N36: 3007940 | O36: SIGGAINT | P36: 46316 | Q36: =IFERROR(VALUE(LEFT($J36,2))*60+VALUE(MID($J36,4,2)),9999) -> 476 | R36: =IFERROR(VALUE(LEFT($K36,2))*60+VALUE(MID($K36,4,2)),"") -> 525 | S36: =IF($Q36<Parâmetros!$E$19,$G36-1,$G36) -> 46316
A37: 9218 | B37: Adriano Donizete Bento da Silva | C37: INS | D37: 46316 | E37: 1.96 | F37: H | G37: 46316 | H37: 40527112 | I37: 10 | J37: 08:45:44 | K37: 10:43:12 | L37: 46316 | M37: LICO | O37: SIGGAINT | P37: 46316 | Q37: =IFERROR(VALUE(LEFT($J37,2))*60+VALUE(MID($J37,4,2)),9999) -> 525 | R37: =IFERROR(VALUE(LEFT($K37,2))*60+VALUE(MID($K37,4,2)),"") -> 643 | S37: =IF($Q37<Parâmetros!$E$19,$G37-1,$G37) -> 46316
A38: 9218 | B38: Adriano Donizete Bento da Silva | C38: INS | D38: 46316 | E38: 1.26 | F38: H | G38: 46316 | H38: 40528179 | I38: 10 | J38: 10:48:12 | K38: 12:04:06 | L38: 46316 | M38: LICO | N38: 3008029 | O38: SIGGAINT | P38: 46316 | Q38: =IFERROR(VALUE(LEFT($J38,2))*60+VALUE(MID($J38,4,2)),9999) -> 648 | R38: =IFERROR(VALUE(LEFT($K38,2))*60+VALUE(MID($K38,4,2)),"") -> 724 | S38: =IF($Q38<Parâmetros!$E$19,$G38-1,$G38) -> 46316
A39: 9218 | B39: Adriano Donizete Bento da Silva | C39: INS | D39: 46316 | E39: 1.65 | F39: H | G39: 46316 | H39: 40526401 | I39: 20 | J39: 13:06:55 | K39: 14:46:03 | L39: 46316 | M39: LICO | O39: SIGGAINT | P39: 46316 | Q39: =IFERROR(VALUE(LEFT($J39,2))*60+VALUE(MID($J39,4,2)),9999) -> 786 | R39: =IFERROR(VALUE(LEFT($K39,2))*60+VALUE(MID($K39,4,2)),"") -> 886 | S39: =IF($Q39<Parâmetros!$E$19,$G39-1,$G39) -> 46316
A40: 9218 | B40: Adriano Donizete Bento da Silva | C40: INS | D40: 46316 | E40: 0.73 | F40: H | G40: 46316 | H40: 40528189 | I40: 10 | J40: 14:52:16 | K40: 15:36:03 | L40: 46316 | M40: LICO | O40: SIGGAINT | P40: 46316 | Q40: =IFERROR(VALUE(LEFT($J40,2))*60+VALUE(MID($J40,4,2)),9999) -> 892 | R40: =IFERROR(VALUE(LEFT($K40,2))*60+VALUE(MID($K40,4,2)),"") -> 936 | S40: =IF($Q40<Parâmetros!$E$19,$G40-1,$G40) -> 46316
...

Sheet Base Diária
A1: Nº pessoal | B1: Empregado | C1: Centro de Trabalho | D1: Escala (cadastro) | E1: Turno cadastro | F1: Data | G1: Dia | H1: 1º apont. (min) | I1: Últ. apont. fim (min) · informativo | J1: Turno esperado (posição) | K1: Turno / jornada aplicada | L1: Horas apontadas | M1: Horas disponíveis | N1: % Apontamento | O1: Meta | P1: Apurado? | Q1: Trabalhou? | R1: Na meta? | S1: Gap p/ meta (h) | T1: Sobre-apontamento? | U1: Situação | V1: Origem do turno / divergência | W1: Seq. dias trabalho | X1: Seq. dias folga | Y1: Tipo de dia | Z1: Ausência seq. (retro) | AA1: Ausência seq. (à frente) | AB1: Linha do cadastro vigente | AC1: Exceção (dia) | AD1: Motivo da exceção
A2: 9218 | B2: Adriano Donizete Bento Da Silva | C2: =IFERROR(INDEX(Cadastro!$C$5:$C$243,$AB2),"NÃO INFORMADO") -> INS | D2: =IFERROR(INDEX(Cadastro!$D$5:$D$243,$AB2),"") -> Férias | E2: =IFERROR(INDEX(Cadastro!$G$5:$G$243,$AB2),"") -> Férias | F2: 46300 | G2: =CHOOSE(WEEKDAY($F2,1),"dom","seg","ter","qua","qui","sex","sáb") -> seg | H2: =IF($L2=0,"",_xlfn.MINIFS(Dados!$Q:$Q,Dados!$A:$A,$A2,Dados!$S:$S,$F2)) | I2: =IF($H2="","",_xlfn.MAXIFS(Dados!$R:$R,Dados!$A:$A,$A2,Dados!$S:$S,$F2)) | J2: =IF($D2<>"Folguista","",IFERROR(INDEX(Parâmetros!$D$52:$G$52,1,MIN(4,MAX(1,$W2))),"")) | K2: =IF(OR($AC2<>"",$Y2="Folga",$Y2="Folga trabalhada",$Y2="Férias (cadastro)",$Y2="Férias / afastamento",$Y2="Indeterminado (início da série)"),"",IF(OR($D2="6x1",$D2="FF 6x1"),IF(OR(WEEKDAY($F2,2)=6,WEEKDAY($F2,2)=7),"6x1 sáb/dom","6x1"),IF($D2="5x2","5x2",IF($H2="",IF($D2="Folguista",$J2,$E2),IF(OR($H2>=Parâmetros!$E$18,$H2<Parâmetros!$E$19),"C",IF($H2<Parâmetros!$E$20,"A","B")))))) | L2: =SUMIFS(Dados!$E:$E,Dados!$A:$A,$A2,Dados!$S:$S,$F2) -> 0 | M2: =IFERROR(INDEX(Parâmetros!$E$6:$E$11,MATCH($K2,Parâmetros!$A$6:$A$11,0)),"") | N2: =IFERROR($L2/$M2,"") | O2: =Parâmetros!$E$13 -> 0.8 | P2: =IF(OR($M2="",$F2>Parâmetros!$E$14),"Não","Sim") -> Não | Q2: =IF($P2="Não","",IF($L2>0,"Sim","Não")) | R2: =IF($Q2<>"Sim","",IF($N2>=$O2,"Sim","Não")) | S2: =IF($Q2<>"Sim","",MAX(0,$M2*$O2-$L2)) | T2: =IF($Q2<>"Sim","",IF($N2>Parâmetros!$E$15,"Sim","Não")) | U2: =IF($AC2<>"",$AC2,IF($P2="Não",IF($Y2="Folga","Folga",IF(LEFT($Y2,6)="Férias","Férias / afastamento",IF($Y2="Indeterminado (início da série)","Início da série","Fora da apuração"))),IF($Q2="Não","Falta de registro",IF($R2="Sim","Na meta","Abaixo da meta")))) -> Férias / afastamento | V2: =IF($AC2<>"",IF($L2>0,"ATENÇÃO · apontou em dia de "&LOWER($AC2)&" cadastrado","Exceção cadastrada · "&$AC2)&IF($AD2="",""," · "&$AD2),IF($E2="Férias",IF($L2>0,"ATENÇÃO · apontou estando de férias no cadastro","Férias no cadastro"),IF($Y2="Férias / afastamento","Afastamento · "&($Z2+$AA2-1)&" dias seguidos sem apontamento",IF($Y2="Folga trabalhada","ATENÇÃO · apontou em dia de folga da escala 5x2",IF($Y2="Folga",IF(AND($D2="5x2",OR(WEEKDAY($F2,2)=6,WEEKDAY($F2,2)=7)),"Folga de fim de semana da escala 5x2",IF(AND(OR($D2="6x1",$D2="FF 6x1"),WEEKDAY($F2,2)=6,FALSE()),"Folga de fim de semana · apontou no domingo anterior",IF(AND(OR($D2="6x1",$D2="FF 6x1"),WEEKDAY($F2,2)=7,AND($A2=$A1,$L1>0)),"Folga de fim de semana · apontou no sábado",IF(AND(OR($D2="6x1",$D2="FF 6x1"),OR(WEEKDAY($F2,2)=6,WEEKDAY($F2,2)=7)),"Folga de fim de semana · sem apontamento no sábado nem no domingo","Folga prevista pelo ciclo")))),IF($Y2="Indeterminado (início da série)","Sem histórico anterior — informe o dia do ciclo no Cadastro",IF($Y2="Falta de registro",IF(OR(OR($D2="6x1",$D2="FF 6x1"),$D2="5x2"),"FALTA DE REGISTRO · dia útil da escala "&$E2,"FALTA DE REGISTRO · dia "&$W2&" de "&IFERROR(INDEX(Parâmetros!$B$39:$B$48,MATCH($E2,Parâmetros!$A$39:$A$48,0)),99)&" do ciclo"),IF(OR($D2="6x1",$D2="FF 6x1"),IF(OR(AND(WEEKDAY($F2,2)=6,AND($A2=$A3,$L3>0)),AND(WEEKDAY($F2,2)=7,AND($A2=$A1,$L1>0))),"ATENÇÃO · apontou sábado e domingo no mesmo fim de semana",IF(OR(WEEKDAY($F2,2)=6,WEEKDAY($F2,2)=7),"Jornada de fim de semana do 6x1",IF(OR($H2>=Parâmetros!$E$20,$H2<Parâmetros!$E$19),"ATENÇÃO · 6x1 apontou fora do horário diurno","Jornada fixa do 6x1"))),IF($D2="5x2","Jornada fixa do 5x2",IF($D2="Folguista",IF($J2=$K2,"Evidência confirma sequência","DIVERGE · sequência "&$J2&" × evidência "&$K2),IF($K2=$E2,"Evidência confirma cadastro","DIVERGE · cadastro "&$E2&" × evidência "&$K2))))))))))) -> Férias no cadastro | W2: =IF(OR(OR($D2="6x1",$D2="FF 6x1"),$D2="5x2"),"",IF($AB2<>$AB1,IF(IFERROR(INDEX(Cadastro!$F$5:$F$243,$AB2),"")="",IF($L2>0,1,0),IF(IFERROR(INDEX(Cadastro!$F$5:$F$243,$AB2),"")<=IFERROR(INDEX(Parâmetros!$B$39:$B$48,MATCH($E2,Parâmetros!$A$39:$A$48,0)),99),IFERROR(INDEX(Cadastro!$F$5:$F$243,$AB2),""),0)),IF($L2>0,IF(N($X1)>0,1,N($W1)+1),IF(AND($L2=0,OR(N($W1)>=IFERROR(INDEX(Parâmetros!$B$39:$B$48,MATCH($E2,Parâmetros!$A$39:$A$48,0)),99),AND(N($X1)>0,N($X1)<IFERROR(INDEX(Parâmetros!$C$39:$C$48,MATCH($E2,Parâmetros!$A$39:$A$48,0)),0)))),0,N($W1)+1)))) -> 0 | X2: =IF(OR(OR($D2="6x1",$D2="FF 6x1"),$D2="5x2"),"",IF($AB2<>$AB1,IF(IFERROR(INDEX(Cadastro!$F$5:$F$243,$AB2),"")="",0,IF(IFERROR(INDEX(Cadastro!$F$5:$F$243,$AB2),"")>IFERROR(INDEX(Parâmetros!$B$39:$B$48,MATCH($E2,Parâmetros!$A$39:$A$48,0)),99),IFERROR(INDEX(Cadastro!$F$5:$F$243,$AB2),"")-IFERROR(INDEX(Parâmetros!$B$39:$B$48,MATCH($E2,Parâmetros!$A$39:$A$48,0)),99),0)),IF(AND($L2=0,OR(N($W1)>=IFERROR(INDEX(Parâmetros!$B$39:$B$48,MATCH($E2,Parâmetros!$A$39:$A$48,0)),99),AND(N($X1)>0,N($X1)<IFERROR(INDEX(Parâmetros!$C$39:$C$48,MATCH($E2,Parâmetros!$A$39:$A$48,0)),0)))),N($X1)+1,0))) -> 0 | Y2: =IF($AC2<>"",IF($L2>0,$AC2&" · com apontamento",$AC2),IF($E2="Férias",IF($L2>0,"Férias · com apontamento","Férias (cadastro)"),IF(($Z2+$AA2-1)>Parâmetros!$E$16,"Férias / afastamento",IF(AND($D2="5x2",OR(WEEKDAY($F2,2)=6,WEEKDAY($F2,2)=7)),IF($L2>0,"Folga trabalhada","Folga"),IF($L2>0,"Trabalhado",IF(OR(OR($D2="6x1",$D2="FF 6x1"),$D2="5x2"),IF(AND(OR($D2="6x1",$D2="FF 6x1"),OR(WEEKDAY($F2,2)=6,WEEKDAY($F2,2)=7)),"Folga","Falta de registro"),IF(AND($AB2<>$AB1,IFERROR(INDEX(Cadastro!$F$5:$F$243,$AB2),"")=""),"Indeterminado (início da série)",IF($X2>0,"Folga","Falta de registro")))))))) -> Férias (cadastro) | Z2: =IF(OR($L2>0,$F2>Parâmetros!$E$14),0,IF($A2<>$A1,1,N($Z1)+1)) -> 1 | AA2: =IF(OR($L2>0,$F2>Parâmetros!$E$14),0,IF(OR($A2<>$A3,$F3>Parâmetros!$E$14),1,N($AA3)+1)) -> 9 | AB2: =IFERROR(MATCH($A2&"|"&TEXT(_xlfn.MAXIFS(Cadastro!$E$5:$E$243,Cadastro!$A$5:$A$243,$A2,Cadastro!$E$5:$E$243,"<="&$F2),"yyyymmdd"),Cadastro!$I$5:$I$243,0),"") -> 4 | AC2: =IFERROR(_xlfn.SINGLE(INDEX(Exceções!$D$5:$D$203,MATCH($A2&"|"&$F2,Exceções!$F$5:$F$203,0))),"") | AD2: =IF($AC2="","",IFERROR(_xlfn.SINGLE(INDEX(Exceções!$E$5:$E$203,MATCH($A2&"|"&$F2,Exceções!$F$5:$F$203,0))),""))
A3: 9218 | B3: Adriano Donizete Bento Da Silva | C3: =IFERROR(INDEX(Cadastro!$C$5:$C$243,$AB3),"NÃO INFORMADO") -> INS | D3: =IFERROR(INDEX(Cadastro!$D$5:$D$243,$AB3),"") -> Férias | E3: =IFERROR(INDEX(Cadastro!$G$5:$G$243,$AB3),"") -> Férias | F3: 46301 | G3: =CHOOSE(WEEKDAY($F3,1),"dom","seg","ter","qua","qui","sex","sáb") -> ter | H3: =IF($L3=0,"",_xlfn.MINIFS(Dados!$Q:$Q,Dados!$A:$A,$A3,Dados!$S:$S,$F3)) | I3: =IF($H3="","",_xlfn.MAXIFS(Dados!$R:$R,Dados!$A:$A,$A3,Dados!$S:$S,$F3)) | J3: =IF($D3<>"Folguista","",IFERROR(INDEX(Parâmetros!$D$52:$G$52,1,MIN(4,MAX(1,$W3))),"")) | K3: =IF(OR($AC3<>"",$Y3="Folga",$Y3="Folga trabalhada",$Y3="Férias (cadastro)",$Y3="Férias / afastamento",$Y3="Indeterminado (início da série)"),"",IF(OR($D3="6x1",$D3="FF 6x1"),IF(OR(WEEKDAY($F3,2)=6,WEEKDAY($F3,2)=7),"6x1 sáb/dom","6x1"),IF($D3="5x2","5x2",IF($H3="",IF($D3="Folguista",$J3,$E3),IF(OR($H3>=Parâmetros!$E$18,$H3<Parâmetros!$E$19),"C",IF($H3<Parâmetros!$E$20,"A","B")))))) | L3: =SUMIFS(Dados!$E:$E,Dados!$A:$A,$A3,Dados!$S:$S,$F3) -> 0 | M3: =IFERROR(INDEX(Parâmetros!$E$6:$E$11,MATCH($K3,Parâmetros!$A$6:$A$11,0)),"") | N3: =IFERROR($L3/$M3,"") | O3: =Parâmetros!$E$13 -> 0.8 | P3: =IF(OR($M3="",$F3>Parâmetros!$E$14),"Não","Sim") -> Não | Q3: =IF($P3="Não","",IF($L3>0,"Sim","Não")) | R3: =IF($Q3<>"Sim","",IF($N3>=$O3,"Sim","Não")) | S3: =IF($Q3<>"Sim","",MAX(0,$M3*$O3-$L3)) | T3: =IF($Q3<>"Sim","",IF($N3>Parâmetros!$E$15,"Sim","Não")) | U3: =IF($AC3<>"",$AC3,IF($P3="Não",IF($Y3="Folga","Folga",IF(LEFT($Y3,6)="Férias","Férias / afastamento",IF($Y3="Indeterminado (início da série)","Início da série","Fora da apuração"))),IF($Q3="Não","Falta de registro",IF($R3="Sim","Na meta","Abaixo da meta")))) -> Férias / afastamento | V3: =IF($AC3<>"",IF($L3>0,"ATENÇÃO · apontou em dia de "&LOWER($AC3)&" cadastrado","Exceção cadastrada · "&$AC3)&IF($AD3="",""," · "&$AD3),IF($E3="Férias",IF($L3>0,"ATENÇÃO · apontou estando de férias no cadastro","Férias no cadastro"),IF($Y3="Férias / afastamento","Afastamento · "&($Z3+$AA3-1)&" dias seguidos sem apontamento",IF($Y3="Folga trabalhada","ATENÇÃO · apontou em dia de folga da escala 5x2",IF($Y3="Folga",IF(AND($D3="5x2",OR(WEEKDAY($F3,2)=6,WEEKDAY($F3,2)=7)),"Folga de fim de semana da escala 5x2",IF(AND(OR($D3="6x1",$D3="FF 6x1"),WEEKDAY($F3,2)=6,FALSE()),"Folga de fim de semana · apontou no domingo anterior",IF(AND(OR($D3="6x1",$D3="FF 6x1"),WEEKDAY($F3,2)=7,AND($A3=$A2,$L2>0)),"Folga de fim de semana · apontou no sábado",IF(AND(OR($D3="6x1",$D3="FF 6x1"),OR(WEEKDAY($F3,2)=6,WEEKDAY($F3,2)=7)),"Folga de fim de semana · sem apontamento no sábado nem no domingo","Folga prevista pelo ciclo")))),IF($Y3="Indeterminado (início da série)","Sem histórico anterior — informe o dia do ciclo no Cadastro",IF($Y3="Falta de registro",IF(OR(OR($D3="6x1",$D3="FF 6x1"),$D3="5x2"),"FALTA DE REGISTRO · dia útil da escala "&$E3,"FALTA DE REGISTRO · dia "&$W3&" de "&IFERROR(INDEX(Parâmetros!$B$39:$B$48,MATCH($E3,Parâmetros!$A$39:$A$48,0)),99)&" do ciclo"),IF(OR($D3="6x1",$D3="FF 6x1"),IF(OR(AND(WEEKDAY($F3,2)=6,AND($A3=$A4,$L4>0)),AND(WEEKDAY($F3,2)=7,AND($A3=$A2,$L2>0))),"ATENÇÃO · apontou sábado e domingo no mesmo fim de semana",IF(OR(WEEKDAY($F3,2)=6,WEEKDAY($F3,2)=7),"Jornada de fim de semana do 6x1",IF(OR($H3>=Parâmetros!$E$20,$H3<Parâmetros!$E$19),"ATENÇÃO · 6x1 apontou fora do horário diurno","Jornada fixa do 6x1"))),IF($D3="5x2","Jornada fixa do 5x2",IF($D3="Folguista",IF($J3=$K3,"Evidência confirma sequência","DIVERGE · sequência "&$J3&" × evidência "&$K3),IF($K3=$E3,"Evidência confirma cadastro","DIVERGE · cadastro "&$E3&" × evidência "&$K3))))))))))) -> Férias no cadastro | W3: =IF(OR(OR($D3="6x1",$D3="FF 6x1"),$D3="5x2"),"",IF($AB3<>$AB2,IF(IFERROR(INDEX(Cadastro!$F$5:$F$243,$AB3),"")="",IF($L3>0,1,0),IF(IFERROR(INDEX(Cadastro!$F$5:$F$243,$AB3),"")<=IFERROR(INDEX(Parâmetros!$B$39:$B$48,MATCH($E3,Parâmetros!$A$39:$A$48,0)),99),IFERROR(INDEX(Cadastro!$F$5:$F$243,$AB3),""),0)),IF($L3>0,IF(N($X2)>0,1,N($W2)+1),IF(AND($L3=0,OR(N($W2)>=IFERROR(INDEX(Parâmetros!$B$39:$B$48,MATCH($E3,Parâmetros!$A$39:$A$48,0)),99),AND(N($X2)>0,N($X2)<IFERROR(INDEX(Parâmetros!$C$39:$C$48,MATCH($E3,Parâmetros!$A$39:$A$48,0)),0)))),0,N($W2)+1)))) -> 1 | X3: =IF(OR(OR($D3="6x1",$D3="FF 6x1"),$D3="5x2"),"",IF($AB3<>$AB2,IF(IFERROR(INDEX(Cadastro!$F$5:$F$243,$AB3),"")="",0,IF(IFERROR(INDEX(Cadastro!$F$5:$F$243,$AB3),"")>IFERROR(INDEX(Parâmetros!$B$39:$B$48,MATCH($E3,Parâmetros!$A$39:$A$48,0)),99),IFERROR(INDEX(Cadastro!$F$5:$F$243,$AB3),"")-IFERROR(INDEX(Parâmetros!$B$39:$B$48,MATCH($E3,Parâmetros!$A$39:$A$48,0)),99),0)),IF(AND($L3=0,OR(N($W2)>=IFERROR(INDEX(Parâmetros!$B$39:$B$48,MATCH($E3,Parâmetros!$A$39:$A$48,0)),99),AND(N($X2)>0,N($X2)<IFERROR(INDEX(Parâmetros!$C$39:$C$48,MATCH($E3,Parâmetros!$A$39:$A$48,0)),0)))),N($X2)+1,0))) -> 0 | Y3: =IF($AC3<>"",IF($L3>0,$AC3&" · com apontamento",$AC3),IF($E3="Férias",IF($L3>0,"Férias · com apontamento","Férias (cadastro)"),IF(($Z3+$AA3-1)>Parâmetros!$E$16,"Férias / afastamento",IF(AND($D3="5x2",OR(WEEKDAY($F3,2)=6,WEEKDAY($F3,2)=7)),IF($L3>0,"Folga trabalhada","Folga"),IF($L3>0,"Trabalhado",IF(OR(OR($D3="6x1",$D3="FF 6x1"),$D3="5x2"),IF(AND(OR($D3="6x1",$D3="FF 6x1"),OR(WEEKDAY($F3,2)=6,WEEKDAY($F3,2)=7)),"Folga","Falta de registro"),IF(AND($AB3<>$AB2,IFERROR(INDEX(Cadastro!$F$5:$F$243,$AB3),"")=""),"Indeterminado (início da série)",IF($X3>0,"Folga","Falta de registro")))))))) -> Férias (cadastro) | Z3: =IF(OR($L3>0,$F3>Parâmetros!$E$14),0,IF($A3<>$A2,1,N($Z2)+1)) -> 2 | AA3: =IF(OR($L3>0,$F3>Parâmetros!$E$14),0,IF(OR($A3<>$A4,$F4>Parâmetros!$E$14),1,N($AA4)+1)) -> 8 | AB3: =IFERROR(MATCH($A3&"|"&TEXT(_xlfn.MAXIFS(Cadastro!$E$5:$E$243,Cadastro!$A$5:$A$243,$A3,Cadastro!$E$5:$E$243,"<="&$F3),"yyyymmdd"),Cadastro!$I$5:$I$243,0),"") -> 4 | AC3: =IFERROR(_xlfn.SINGLE(INDEX(Exceções!$D$5:$D$203,MATCH($A3&"|"&$F3,Exceções!$F$5:$F$203,0))),"") | AD3: =IF($AC3="","",IFERROR(_xlfn.SINGLE(INDEX(Exceções!$E$5:$E$203,MATCH($A3&"|"&$F3,Exceções!$F$5:$F$203,0))),""))
